<?xml version="1.0"?>
<!-- URDF used for generating xml model -->
<robot name="furuta_pendulum">
  <material name="grey">
    <color rgba="0.8 0.8 0.8 1.0" />
  </material>
  <material name="yellow">
    <color rgba="1.0 1.0 0.0 1.0" />
  </material>

  <link name="base_link">
    <visual>
      <origin rpy="1.57079632679 0.0 0.0" xyz="0.0 0.0 0.0" />
      <geometry>
        <mesh filename="37d_motor_mount.stl" scale="0.001 0.001 0.001"/>
      </geometry>
      <material name="yellow" />
    </visual>
    <collision>
      <origin rpy="0.0 0.0 0.0" xyz="0.0 0.0 0.0895" />
      <geometry>
        <cylinder length="0.179" radius="0.025" />
      </geometry>
    </collision>
    <inertial>
      <mass value="0.0" />
      <origin rpy="0.0 0.0 0.0" xyz="0.0 0.0 0.0" />
      <inertia ixx="0.0" ixy="0.0" ixz="0.0" iyy="0.0" iyz="0.0" izz="0.0" />
    </inertial>
  </link>

  <joint name="joint0" type="revolute">
    <origin rpy="0.0 0.0 0.0" xyz="0.0 0.0 0.095" />
    <parent link="base_link" />
    <child link="arm1" />
    <axis xyz="0 0 1" />
    <dynamics damping="0.0001" />
    <limit effort="1000" lower="-10" upper="10" velocity="1000"/>
  </joint>

  <link name="arm1">
    <visual>
      <origin rpy="0.0 1.5707963267948966 0.0" xyz="0.0 0.0 0.0" />
      <geometry>
        <cylinder length="0.2" radius="0.005" />
      </geometry>
      <material name="grey" />
    </visual>
    <collision>
      <origin rpy="0.0 1.5707963267948966 0.0" xyz="0.0467625 0.0 0.0" />
      <geometry>
        <cylinder length="0.093525" radius="0.005" />
      </geometry>
    </collision>
    <inertial>
      <mass value="0.0" />
      <origin rpy="0.0 0.0 0.0" xyz="0.0 0.0 0.0" />
      <inertia ixx="0.0" ixy="0.0" ixz="0.0" iyy="0.0" iyz="0.0" izz="0.0" />
    </inertial>
  </link>

  <joint name="joint6" type="fixed">
    <origin rpy="0.0 0.0 0.0" xyz="0.0 0.0 -0.015" />
    <parent link="arm1" />
    <child link="arm_mount" />
  </joint>

  <link name="arm_mount">
    <visual>
      <origin rpy="1.5707963267948966 0.0 0.0" xyz="0.0 0.0 0.0" />
      <geometry>
        <mesh filename="37d_arm.stl" scale="0.001 0.001 0.001"/>
      </geometry>
      <material name="yellow" />
    </visual>
    <collision>
      <origin rpy="0.0 1.5707963267948966 0.0" xyz="0.0467625 0.0 0.0" />
      <geometry>
        <cylinder length="0.093525" radius="0.005" />
      </geometry>
    </collision>
    <inertial>
      <mass value="0.0" />
      <origin rpy="0.0 0.0 0.0" xyz="0.0 0.0 0.0" />
      <inertia ixx="0.0" ixy="0.0" ixz="0.0" iyy="0.0" iyz="0.0" izz="0.0" />
    </inertial>
  </link>

  <joint name="joint1" type="revolute">
    <!-- -pi rotation so that for 0 pendulum is downward -->
    <origin rpy="0.0 0.0 0.0" xyz="0.1 0.0 0.0" />
    <parent link="arm1" />
    <child link="arm2" />
    <axis xyz="1 0 0" />
    <dynamics damping="1.7905703040590617e-05" />
    <limit effort="1000" lower="-10" upper="10" velocity="1000"/>
  </joint>

  <link name="arm2">
    <visual>
      <origin rpy="0.0 0.0 0.0" xyz="0.0 0.0 0.05" />
      <geometry>
        <cylinder length="0.1" radius="0.005" />
      </geometry>
      <material name="grey" />
    </visual>
    <collision>
      <origin rpy="0.0 0.0 0.0" xyz="0.0 0.0 0.0645" />
      <geometry>
        <cylinder length="0.129" radius="0.005" />
      </geometry>
    </collision>
    <inertial>
      <mass value="0.0" />
      <origin rpy="0.0 0.0 0.0" xyz="0.0 0.0 0.0" />
      <inertia ixx="0.0" ixy="0.0" ixz="0.0" iyy="0.0" iyz="0.0" izz="0.0" />
    </inertial>
  </link>

  <joint name="joint2" type="fixed">
    <origin rpy="0.0 0.0 0.0" xyz="0.0 0.0 0.1" />
    <parent link="arm2" />
    <child link="mass" />
  </joint>

    <link name="mass">
        <visual>
        <origin rpy="1.57079632679 0.0 0.0" xyz="0.0 -0.04 0.0" />
        <geometry>
            <mesh filename="m14_weight.stl" scale="0.001 0.001 0.001"/>
        </geometry>
        <material name="yellow" />
        </visual>
        <inertial>
            <mass value="0.1" />
            <origin rpy="0.0 0.0 0.0" xyz="0.0 0.0 0.0" />
            <inertia ixx="0." ixy="0.0" ixz="0.0" iyy="0.0" iyz="0.0" izz="0.0" />
        </inertial>
    </link>
</robot>
