<robot name="penduli">

    <link name="base_link">
        <visual>
            <origin xyz="0 0 0" rpy="0 -0 0" />
            <geometry>
                <mesh filename="package:///base_link_visual.stl"/>
            </geometry>
            <material name="base_link_material">
                <color rgba="0.5 0.5 0.5 1.0"/>
            </material>
        </visual>
        <inertial>
            <origin xyz="0 0 0" rpy="0 0 0"/>
            <mass value="0" />
            <inertia ixx="0" ixy="0"  ixz="0" iyy="0" iyz="0" izz="0" />
        </inertial>
    </link>

    <link name="arm">
        <visual>
            <origin xyz="0 0 0" rpy="0 -0 0" />
            <geometry>
                <mesh filename="package:///arm_visual.stl"/>
            </geometry>
            <material name="arm_material">
                <color rgba="0.56796738497379162247 0.61999611725878478463 0.64309842748980772242 1.0"/>
            </material>
        </visual>
        <inertial>
            <origin xyz="-0.012730712527184204208 8.0648459397807153353e-05 0.005695644985026769927" rpy="0 0 0"/>
            <mass value="0.053300000000000000155" />
            <inertia ixx="8.5501438448210958501e-06" ixy="6.7935725380048332954e-08"  ixz="-2.9080329526919720674e-07" iyy="4.0401626057956908748e-05" iyz="3.8704860075728652954e-08" izz="3.9415181227059347974e-05" />
        </inertial>
    </link>

    <link name="pendulum">
        <visual>
            <origin xyz="0 0 0" rpy="0 -0 0" />
            <geometry>
                <mesh filename="package:///pendulum_visual.stl"/>
            </geometry>
            <material name="pendulum_material">
                <color rgba="0.76862745098039209068 0.88627450980392152857 0.95294117647058818044 1.0"/>
            </material>
        </visual>
        <inertial>
            <origin xyz="-3.9121175587740948415e-05 -0.057178101805345715736 0.043492661954719007145" rpy="0 0 0"/>
            <mass value="0.045800000000000007372" />
            <inertia ixx="0.00011055395208428459041" ixy="1.0796944809187548275e-07"  ixz="-8.9184870386278528739e-08" iyy="4.2567254327530024811e-05" iyz="4.3210612137898138244e-05" izz="6.9795432247388833726e-05" />
        </inertial>
    </link>

    <joint name="arm" type="revolute">
        <origin xyz="-0.0040000000000000139611 -1.3010426069826053208e-18 0.0091500000000000053513" rpy="-1.570796326794896558 3.141592653589793 1.5707963267948801267" />
        <parent link="arm" />
        <child link="pendulum" />
        <axis xyz="0 0 1"/>
        <limit effort="1" velocity="20" />
        <joint_properties friction="0.0"/>
    </joint>

    <joint name="base_link" type="revolute">
        <origin xyz="0.0031935242862665912632 -0.0071650681287528461896 0.090081326273058190401" rpy="3.0839735524825034295e-14 3.011479954295665724e-15 1.5707963267948303887" />
        <parent link="base_link" />
        <child link="arm" />
        <axis xyz="0 0 1"/>
        <limit effort="1" velocity="20" />
        <joint_properties friction="0.0"/>
    </joint>

</robot>
